Workbook

Sheet Board
D5: VENUE | E5: WALL | F5: PRICE | G5: DECIMAL | H5: IMPLIED | I5: BOOK | J5: TRUE | K5: RANK | L5: STATUS | M5: CHECKED
D6: Bet 365 | E6: OPEN | F6: 8/1 | G6: =IFERROR(LEFT(F6,FIND("/",F6)-1)/MID(F6,FIND("/",F6)+1,9)+1,"ERR PRICE") -> 9 | H6: =IFERROR(1/G6,"ERR") -> 0.11111111 | I6: 1.178 | J6: =IFERROR(H6/I6,"ERR") -> 0.094321826 | K6: 4 | L6: LIVE | M6: 0.51041667
D7: Draftkings | E7: BLOCKED | F7: 8/1 | G7: =IFERROR(LEFT(F7,FIND("/",F7)-1)/MID(F7,FIND("/",F7)+1,9)+1,"ERR PRICE") -> 9 | H7: =IFERROR(1/G7,"ERR") -> 0.11111111 | I7: 1.1604 | J7: =IFERROR(H7/I7,"ERR") -> 0.095752423 | K7: 3 | L7: NO ACCESS | M7: 0.50069444
D8: Ladbrokes | E8: OPEN | F8: 8/1 | G8: =IFERROR(LEFT(F8,FIND("/",F8)-1)/MID(F8,FIND("/",F8)+1,9)+1,"ERR PRICE") -> 9 | H8: =IFERROR(1/G8,"ERR") -> 0.11111111 | I8: 1.1231 | J8: =IFERROR(H8/I8,"ERR") -> 0.098932518 | K8: 1 | L8: LIVE | M8: 0.50138889
D9: AK Bets | E9: OPEN | F9: 9/1 | G9: =IFERROR(LEFT(F9,FIND("/",F9)-1)/MID(F9,FIND("/",F9)+1,9)+1,"ERR PRICE") -> 10 | H9: =IFERROR(1/G9,"ERR") -> 0.1 | I9: 1.0361 | J9: =IFERROR(H9/I9,"ERR") -> 0.09651578 | K9: 2 | L9: LIVE | M9: 0.51180556
D10: Betfair | E10: OPEN | F10: 17/2 | G10: =IFERROR(LEFT(F10,FIND("/",F10)-1)/MID(F10,FIND("/",F10)+1,9)+1,"ERR PRICE") -> 9.5 | H10: =IFERROR(1/G10,"ERR") -> 0.10526316 | I10: 1.1495 | J10: =IFERROR(H10/I10,"ERR") -> 0.091572995 | K10: 5 | L10: LIVE | M10: 0.5125
D13: THE HONEST NUMBER 9.8% | G13: BEST PAYOUT 9/1 | J13: EDGE AT BEST PRICE -0.11pp
D16: Ladbrokes fancies Chelsea most at a 9.9% true probability

Sheet Market
A1: PREDICTION | B1: 0
E2: BET 365 | I2: AK BETS | M2: BETFAIR | Q2: Draftkings | U2: Ladbrokes
A4: BEST BACK | B4: EXCH LAY | C4: GAP % | D4: SEEN AT | E4: Team | F4: BET365 DEC | G4: BET365 IMPLIED | I4: Team | J4: AK BETS DEC | K4: AK BETS IMPLIED | M4: Team | N4: BETFAIR DEC | O4: BETFAIR IMPLIED | Q4: Team | R4: DRAFTKINGS DEC | S4: DRAFTKINGS IMPLIED | U4: Team | V4: LADBROKES DEC | W4: LADBROKES IMPLIED
A5: =MAX(F5,J5,N5,R5,V5) -> 2.5 | B5: 1.92 | C5: =IFERROR(A5/B5-1,"ERR") -> 0.30208333 | D5: 0.49652778 | E5: Arsenal | F5: 2.5 | G5: =1/F5 -> 0.4 | I5: Arsenal | J5: 2.25 | K5: =1/J5 -> 0.44444444 | M5: Arsenal | N5: 2.25 | O5: =1/N5 -> 0.44444444 | Q5: Arsenal | R5: 2.4 | S5: =1/R5 -> 0.41666667 | U5: Arsenal | V5: 2.25 | W5: =1/V5 -> 0.44444444
A6: =MAX(F6,J6,N6,R6,V6) -> 81 | B6: 180 | C6: =IFERROR(A6/B6-1,"ERR") -> -0.55 | D6: 0.49722222 | E6: Aston Villa | F6: 41 | G6: =1/F6 -> 0.024390244 | I6: Aston Villa | J6: 81 | K6: =1/J6 -> 0.012345679 | M6: Aston Villa | N6: 41 | O6: =1/N6 -> 0.024390244 | Q6: Aston Villa | R6: 51 | S6: =1/R6 -> 0.019607843 | U6: Aston Villa | V6: 67 | W6: =1/V6 -> 0.014925373
A7: =MAX(F7,J7,N7,R7,V7) -> 501 | B7: 1000 | C7: =IFERROR(A7/B7-1,"ERR") -> -0.499 | D7: 0.49722222 | E7: Bournemouth | F7: 201 | G7: =1/F7 -> 0.0049751244 | I7: Bournemouth | J7: 501 | K7: =1/J7 -> 0.001996008 | M7: Bournemouth | N7: 301 | O7: =1/N7 -> 0.0033222591 | Q7: Bournemouth | R7: 251 | S7: =1/R7 -> 0.0039840637 | U7: Bournemouth | V7: 201 | W7: =1/V7 -> 0.0049751244
A8: =MAX(F8,J8,N8,R8,V8) -> 301 | B8: 180 | C8: =IFERROR(A8/B8-1,"ERR") -> 0.67222222 | D8: 0.49722222 | E8: Brentford | F8: 251 | G8: =1/F8 -> 0.0039840637 | I8: Brentford | J8: 301 | K8: =1/J8 -> 0.0033222591 | M8: Brentford | N8: 301 | O8: =1/N8 -> 0.0033222591 | Q8: Brentford | R8: 251 | S8: =1/R8 -> 0.0039840637 | U8: Brentford | V8: 251 | W8: =1/V8 -> 0.0039840637
A9: =MAX(F9,J9,N9,R9,V9) -> 301 | B9: 190 | C9: =IFERROR(A9/B9-1,"ERR") -> 0.58421053 | D9: 0.49722222 | E9: Brighton | F9: 151 | G9: =1/F9 -> 0.0066225166 | I9: Brighton | J9: 301 | K9: =1/J9 -> 0.0033222591 | M9: Brighton | N9: 176 | O9: =1/N9 -> 0.0056818182 | Q9: Brighton | R9: 151 | S9: =1/R9 -> 0.0066225166 | U9: Brighton | V9: 201 | W9: =1/V9 -> 0.0049751244
A10: =MAX(F10,J10,N10,R10,V10) -> 10 | B10: 10 | C10: =IFERROR(A10/B10-1,"ERR") -> 0 | D10: 0.49722222 | E10: Chelsea | F10: 9 | G10: =1/F10 -> 0.11111111 | I10: Chelsea | J10: 10 | K10: =1/J10 -> 0.1 | M10: Chelsea | N10: 9 | O10: =1/N10 -> 0.11111111 | Q10: Chelsea | R10: 9 | S10: =1/R10 -> 0.11111111 | U10: Chelsea | V10: 9 | W10: =1/V10 -> 0.11111111
A11: =MAX(F11,J11,N11,R11,V11) -> 2001 | C11: =IFERROR(A11/B11-1,"ERR") -> ERR | D11: 0.49722222 | E11: Coventry City | F11: 2001 | G11: =1/F11 -> 0.00049975012 | I11: Coventry City | J11: 1001 | K11: =1/J11 -> 0.000999001 | M11: Coventry City | N11: 501 | O11: =1/N11 -> 0.001996008 | Q11: Coventry City | R11: 1001 | S11: =1/R11 -> 0.000999001 | U11: Coventry City | V11: 1001 | W11: =1/V11 -> 0.000999001
A12: =MAX(F12,J12,N12,R12,V12) -> 1001 | C12: =IFERROR(A12/B12-1,"ERR") -> ERR | D12: 0.49722222 | E12: Crystal Palace | F12: 501 | G12: =1/F12 -> 0.001996008 | I12: Crystal Palace | J12: 1001 | K12: =1/J12 -> 0.000999001 | M12: Crystal Palace | N12: 501 | O12: =1/N12 -> 0.001996008 | Q12: Crystal Palace | R12: 251 | S12: =1/R12 -> 0.0039840637 | U12: Crystal Palace | V12: 501 | W12: =1/V12 -> 0.001996008
A13: =MAX(F13,J13,N13,R13,V13) -> 501 | B13: 950 | C13: =IFERROR(A13/B13-1,"ERR") -> -0.47263158 | D13: 0.49722222 | E13: Everton | F13: 251 | G13: =1/F13 -> 0.0039840637 | I13: Everton | J13: 501 | K13: =1/J13 -> 0.001996008 | M13: Everton | N13: 301 | O13: =1/N13 -> 0.0033222591 | Q13: Everton | R13: 251 | S13: =1/R13 -> 0.0039840637 | U13: Everton | V13: 251 | W13: =1/V13 -> 0.0039840637
A14: =MAX(F14,J14,N14,R14,V14) -> 501 | C14: =IFERROR(A14/B14-1,"ERR") -> ERR | D14: 0.49722222 | E14: Fulham | F14: 501 | G14: =1/F14 -> 0.001996008 | I14: Fulham | J14: 501 | K14: =1/J14 -> 0.001996008 | M14: Fulham | N14: 501 | O14: =1/N14 -> 0.001996008 | Q14: Fulham | R14: 501 | S14: =1/R14 -> 0.001996008 | U14: Fulham | V14: 501 | W14: =1/V14 -> 0.001996008
A15: =MAX(F15,J15,N15,R15,V15) -> 2001 | C15: =IFERROR(A15/B15-1,"ERR") -> ERR | D15: 0.49722222 | E15: Hull City | F15: 2001 | G15: =1/F15 -> 0.00049975012 | I15: Hull City | J15: 2001 | K15: =1/J15 -> 0.00049975012 | M15: Hull City | N15: 501 | O15: =1/N15 -> 0.001996008 | Q15: Hull City | R15: 2001 | S15: =1/R15 -> 0.00049975012 | U15: Hull City | V15: 2001 | W15: =1/V15 -> 0.00049975012
A16: =MAX(F16,J16,N16,R16,V16) -> 3001 | C16: =IFERROR(A16/B16-1,"ERR") -> ERR | D16: 0.49722222 | E16: Ipswich Town | F16: 3001 | G16: =1/F16 -> 0.00033322226 | I16: Ipswich Town | J16: 1001 | K16: =1/J16 -> 0.000999001 | M16: Ipswich Town | N16: 501 | O16: =1/N16 -> 0.001996008 | Q16: Ipswich Town | R16: 1001 | S16: =1/R16 -> 0.000999001 | U16: Ipswich Town | V16: 1001 | W16: =1/V16 -> 0.000999001
A17: =MAX(F17,J17,N17,R17,V17) -> 501 | B17: 400 | C17: =IFERROR(A17/B17-1,"ERR") -> 0.2525 | D17: 0.49722222 | E17: Leeds United | F17: 501 | G17: =1/F17 -> 0.001996008 | I17: Leeds United | J17: 501 | K17: =1/J17 -> 0.001996008 | M17: Leeds United | N17: 301 | O17: =1/N17 -> 0.0033222591 | Q17: Leeds United | R17: 251 | S17: =1/R17 -> 0.0039840637 | U17: Leeds United | V17: 501 | W17: =1/V17 -> 0.001996008
A18: =MAX(F18,J18,N18,R18,V18) -> 7 | B18: 10.5 | C18: =IFERROR(A18/B18-1,"ERR") -> -0.33333333 | D18: 0.49722222 | E18: Liverpool | F18: 6 | G18: =1/F18 -> 0.16666667 | I18: Liverpool | J18: 7 | K18: =1/J18 -> 0.14285714 | M18: Liverpool | N18: 6.5 | O18: =1/N18 -> 0.15384615 | Q18: Liverpool | R18: 6 | S18: =1/R18 -> 0.16666667 | U18: Liverpool | V18: 7 | W18: =1/V18 -> 0.14285714
A19: =MAX(F19,J19,N19,R19,V19) -> 4.75 | B19: 5.4 | C19: =IFERROR(A19/B19-1,"ERR") -> -0.12037037 | D19: 0.49722222 | E19: Manchester City | F19: 3.75 | G19: =1/F19 -> 0.26666667 | I19: Manchester City | J19: 4.75 | K19: =1/J19 -> 0.21052632 | M19: Manchester City | N19: 4 | O19: =1/N19 -> 0.25 | Q19: Manchester City | R19: 4 | S19: =1/R19 -> 0.25 | U19: Manchester City | V19: 4.33 | W19: =1/V19 -> 0.23094688
A20: =MAX(F20,J20,N20,R20,V20) -> 13 | B20: 21 | C20: =IFERROR(A20/B20-1,"ERR") -> -0.38095238 | D20: 0.49722222 | E20: Manchester United | F20: 8 | G20: =1/F20 -> 0.125 | I20: Manchester United | J20: 13 | K20: =1/J20 -> 0.076923077 | M20: Manchester United | N20: 9.5 | O20: =1/N20 -> 0.10526316 | Q20: Manchester United | R20: 9 | S20: =1/R20 -> 0.11111111 | U20: Manchester United | V20: 9 | W20: =1/V20 -> 0.11111111
A21: =MAX(F21,J21,N21,R21,V21) -> 276 | B21: 370 | C21: =IFERROR(A21/B21-1,"ERR") -> -0.25405405 | D21: 0.49722222 | E21: Newcastle United | F21: 151 | G21: =1/F21 -> 0.0066225166 | I21: Newcastle United | J21: 276 | K21: =1/J21 -> 0.0036231884 | M21: Newcastle United | N21: 176 | O21: =1/N21 -> 0.0056818182 | Q21: Newcastle United | R21: 151 | S21: =1/R21 -> 0.0066225166 | U21: Newcastle United | V21: 151 | W21: =1/V21 -> 0.0066225166
A22: =MAX(F22,J22,N22,R22,V22) -> 501 | B22: 1000 | C22: =IFERROR(A22/B22-1,"ERR") -> -0.499 | D22: 0.49722222 | E22: Nottingham Forest | F22: 501 | G22: =1/F22 -> 0.001996008 | I22: Nottingham Forest | J22: 501 | K22: =1/J22 -> 0.001996008 | M22: Nottingham Forest | N22: 301 | O22: =1/N22 -> 0.0033222591 | Q22: Nottingham Forest | R22: 501 | S22: =1/R22 -> 0.001996008 | U22: Nottingham Forest | V22: 251 | W22: =1/V22 -> 0.0039840637
A23: =MAX(F23,J23,N23,R23,V23) -> 1001 | B23: 1000 | C23: =IFERROR(A23/B23-1,"ERR") -> 0.001 | D23: 0.49722222 | E23: Sunderland | F23: 751 | G23: =1/F23 -> 0.0013315579 | I23: Sunderland | J23: 1001 | K23: =1/J23 -> 0.000999001 | M23: Sunderland | N23: 501 | O23: =1/N23 -> 0.001996008 | Q23: Sunderland | R23: 501 | S23: =1/R23 -> 0.001996008 | U23: Sunderland | V23: 751 | W23: =1/V23 -> 0.0013315579
A24: =MAX(F24,J24,N24,R24,V24) -> 41 | B24: 60 | C24: =IFERROR(A24/B24-1,"ERR") -> -0.31666667 | D24: 0.49722222 | E24: Tottenham | F24: 21 | G24: =1/F24 -> 0.047619048 | I24: Tottenham | J24: 41 | K24: =1/J24 -> 0.024390244 | M24: Tottenham | N24: 29 | O24: =1/N24 -> 0.034482759 | Q24: Tottenham | R24: 23 | S24: =1/R24 -> 0.043478261 | U24: Tottenham | V24: 34 | W24: =1/V24 -> 0.029411765
G25: 1.1783 | K25: 1.0361 | O25: 1.1634 | S25: 1.1604 | W25: 1.1231

Sheet Matches
D1: =IF(COUNTIF(D3:D5,"ERR")>0,"ERR IN BOOK",SUM(D3:D5)) -> 1.0847159 | E1: =IF(ISNUMBER($D$1),$D$1-1,"ERR") -> 0.084715938
A2: WHO | B2: PRICE | C2: DEC | D2: IMPLIED | E2: TRUE
A3: HOME | B3: 12/5 | C3: =IFERROR(IF(ISNUMBER(FIND("/",B3)),LEFT(B3,FIND("/",B3)-1)/MID(B3,FIND("/",B3)+1,9)+1,VALUE(B3)),"ERR") -> 3.4 | D3: =IFERROR(1/C3,"ERR") -> 0.29411765 | E3: =IFERROR(D3/SUM($D$3:$D$5), "") -> 0.27114716
A4: DRAW | B4: 13/5 | C4: =IFERROR(IF(ISNUMBER(FIND("/",B4)),LEFT(B4,FIND("/",B4)-1)/MID(B4,FIND("/",B4)+1,9)+1,VALUE(B4)),"ERR") -> 3.6 | D4: =IFERROR(1/C4,"ERR") -> 0.27777778 | E4: =IFERROR(D4/$D$1,"ERR") -> 0.25608343
A5: AWAY | B5: 19/20 | C5: =IFERROR(IF(ISNUMBER(FIND("/",B5)),LEFT(B5,FIND("/",B5)-1)/MID(B5,FIND("/",B5)+1,9)+1,VALUE(B5)),"ERR") -> 1.95 | D5: =IFERROR(1/C5,"ERR") -> 0.51282051 | E5: =IFERROR(D5/$D$1,"ERR") -> 0.47276941
B8: Fulham vs Chelsea

Sheet Scorers
D1: =IF(COUNTIF(D3:D5,"ERR")>0,"ERR IN BOOK",SUM(D3:D12)) -> 0.91992477
A2: WHO | B2: PRICE | C2: DEC | D2: IMPLIED
A3: Cole Palmer | B3: 46027 | C3: =IFERROR(IF(ISNUMBER(FIND("/",B3)),LEFT(B3,FIND("/",B3)-1)/MID(B3,FIND("/",B3)+1,9)+1,VALUE(B3)),"ERR") -> 6 | D3: =IFERROR(1/C3,"ERR") -> 0.16666667
A4: Danny Welbeck | B4: 46064 | C4: =IFERROR(IF(ISNUMBER(FIND("/",B4)),LEFT(B4,FIND("/",B4)-1)/MID(B4,FIND("/",B4)+1,9)+1,VALUE(B4)),"ERR") -> 6.5 | D4: =IFERROR(1/C4,"ERR") -> 0.15384615 | G4: PARTIAL — more scorers exist, real total higher.
A5: Rodrigo Muniz | B5: 46066 | C5: =IFERROR(IF(ISNUMBER(FIND("/",B5)),LEFT(B5,FIND("/",B5)-1)/MID(B5,FIND("/",B5)+1,9)+1,VALUE(B5)),"ERR") -> 7.5 | D5: =IFERROR(1/C5,"ERR") -> 0.13333333
A6: Jamie Gittens | B6: 46032 | C6: =IFERROR(IF(ISNUMBER(FIND("/",B6)),LEFT(B6,FIND("/",B6)-1)/MID(B6,FIND("/",B6)+1,9)+1,VALUE(B6)),"ERR") -> 11 | D6: =IFERROR(1/C6,"ERR") -> 0.090909091
A7: Gonzalo Garcia | B7: 46030 | C7: =IFERROR(IF(ISNUMBER(FIND("/",B7)),LEFT(B7,FIND("/",B7)-1)/MID(B7,FIND("/",B7)+1,9)+1,VALUE(B7)),"ERR") -> 9 | D7: =IFERROR(1/C7,"ERR") -> 0.11111111
A8: Enzo Fernandez | B8: 46034 | C8: =IFERROR(IF(ISNUMBER(FIND("/",B8)),LEFT(B8,FIND("/",B8)-1)/MID(B8,FIND("/",B8)+1,9)+1,VALUE(B8)),"ERR") -> 13 | D8: =IFERROR(1/C8,"ERR") -> 0.076923077
A9: Oscar Bobb | B9: 46036 | C9: =IFERROR(IF(ISNUMBER(FIND("/",B9)),LEFT(B9,FIND("/",B9)-1)/MID(B9,FIND("/",B9)+1,9)+1,VALUE(B9)),"ERR") -> 15 | D9: =IFERROR(1/C9,"ERR") -> 0.066666667
A10: Mamadou Sarr | B10: 33/1 | C10: =IFERROR(IF(ISNUMBER(FIND("/",B10)),LEFT(B10,FIND("/",B10)-1)/MID(B10,FIND("/",B10)+1,9)+1,VALUE(B10)),"ERR") -> 34 | D10: =IFERROR(1/C10,"ERR") -> 0.029411765
A11: Calvin Bassey | B11: 40/1 | C11: =IFERROR(IF(ISNUMBER(FIND("/",B11)),LEFT(B11,FIND("/",B11)-1)/MID(B11,FIND("/",B11)+1,9)+1,VALUE(B11)),"ERR") -> 41 | D11: =IFERROR(1/C11,"ERR") -> 0.024390244
A12: No SCORER | B12: 46036 | C12: =IFERROR(IF(ISNUMBER(FIND("/",B12)),LEFT(B12,FIND("/",B12)-1)/MID(B12,FIND("/",B12)+1,9)+1,VALUE(B12)),"ERR") -> 15 | D12: =IFERROR(1/C12,"ERR") -> 0.066666667

Sheet COMPS
B2: DATE | C2: TITLE | D2: SOLD (£) | E2: POSTAGE (£) | F2: Seller (UK) | G2: Link
B3: 46235 | C3: Pokémon Korean Munikis / Nihil Zero [M3] Booster Box | D3: 39.95 | E3: 0 | F3: Ebay | G3: https://www.ebay.co.uk/itm/257415479506?_skw=korean+pokemon+booster+box&itmmeta=01M0CTJWS454E7H3TGB6Z8T11P&hash=item3bef2880d2:g:uTsAAeSwv7lpvG5Q&itmprp=enc%3AAQALAAAA8GfYFPkwiKCW4ZNSs2u11xAOe0Y58Js%2B8RHEq5TKs8wMXUMb3beNuLDqUuExKwTXVKoWWWUueiMT5F99hK5accjm1lOrwbttUJ%2BV8I34vz%2BmlnpQ83b1U--iayGn%2B0p6r2g89dEwQ%2BffpaGSWDeLSlsXIERxiYV5wyeLEUwW6lFF3I8mU0yRk1QHIZjdspPlfSOS6m8MqDoHaFMtXB8WINWQBJ7mfUG89slouFk%2FzYtxBZYw6NbVK64B5rtovdZlJIAB2EqAcU%2BUrfaBc2cSTS485O0eGigMZOd0b8oAbvD0cWiPybwjjpI4Vo1SR2kWJQ%3D%3D%7Ctkp%3ABFBM6szLmoNo
B4: 46236 | C4: Pokemon TCG | Nihil Zero | Munikis Zero | M3 | Korean | Booster Box | D4: 54.99 | E4: 3.95 | F4: Amazon | G4: https://www.amazon.co.uk/Pokemon-Munikis-M3-Booster-Collectors/dp/B0H37N66LC/ref=asc_df_B0H37N66LC?mcid=befdc165edbb3acfad3c53eb7ba906f5&tag=googshopuk-21&linkCode=df0&hvadid=791198028413&hvpos=&hvnetw=g&hvrand=16774976478424918764&hvpone=&hvptwo=&hvqmt=&hvdev=c&hvdvcmdl=&hvlocint=&hvlocphy=9044956&hvtargid=pla-2493029932772&psc=1&hvocijid=16774976478424918764-B0H37N66LC-&hvexpln=0&gad_source=1
B5: 46237 | C5: Pokemon TCG: Nihil Zero m3 - Korean Booster Box (30 Packs) | D5: 44.95 | E5: 0 | F5: Romulus Games | G5: https://romulusgames.com/products/pokemon-tcg-nihil-zero-m3-korean-booster-box?variant=56867831218553&country=GB&currency=GBP&utm_medium=product_sync&utm_source=google&utm_content=sag_organic&utm_campaign=sag_organic&gad_source=1&gad_campaignid=20585219644&gbraid=0AAAAApH777K0fokTM5za5Rs05rz-fveve&gclid=CjwKCAjwqJXUBhBNEiwA8BgG7uSRVQ4z-9z_6xslNDGygv5RBdgz10-SUkFXSRZp-d2-7fEzdKy3JRoCByAQAvD_BwE
B6: 46238 | C6: Pokémon Korean Munikis / Nihil Zero [M3] Booster Box (30 Packs) | D6: 41.99 | E6: 0 | F6: Ebay | G6: https://www.ebay.co.uk/itm/147403148576?_skw=Pok%C3%A9mon+Korean+Munikis+%2F+Nihil+Zero+%5BM3%5D+Booster+Box&itmmeta=01M0CV3R2A2MYZ78QKCDBZ0JPY&hash=item2251e98d20:g:BuAAAeSwlQtqQVCn&itmprp=enc%3AAQALAAABEGfYFPkwiKCW4ZNSs2u11xC04i%2BbhZ9eovUPyp4BY5rumLEpnPmrrXtddn0gIe35QWBAeJMb9nKnc2MXMcs6kF0NoEEdlj9TUQr9MxgsuK4wCYVGHpDkLkA83g4bZvCWwa3P8YJ3paPvwo%2FQxv3QfXpRqqL2kNkry8V%2Fw2TGgWnFYv940ewIiGWBnCg8%2BWlXPtbkxsQNfQbiCjyUd5MRqHeJ0fyl%2BUhIt9tHXfkGHFInMXv4YmM9U0NPEHwhAZd7szwqFgTNDJcj%2FuRL2YrvQlrMBZk6HRNBcCnaGAUz3UcS--Xd%2BixhAkJC6d9VMHvOwIpCrr1hXg2hx0TOyThtZ3kin%2Fc7%2FB6vnZoufe0750Rq%7Ctkp%3ABk9SR8aBj5uDaA
B7: 46239 | C7: Pokémon Korean Munikis / Nihil Zero [M3] Booster Box (30 Packs) - New & Sealed | D7: 37.1 | E7: 0 | F7: Ebay | G7: https://www.ebay.co.uk/itm/236848103670?_skw=Pok%C3%A9mon+Korean+Munikis+booster+box&itmmeta=01M0CVAKR99V6JF7XDXWTHWJ99&hash=item37253f40f6:g:0QQAAeSwS5JqHAsS&itmprp=enc%3AAQALAAAA4GfYFPkwiKCW4ZNSs2u11xCJ3tsYl1tLw6U%2Bdonc36czC0JLTSwmqipIFNdQmMzpxLq5xUa8mfnOVjfnYdJDL0O7B6ATr6AE6IiM8VVwWhwMl1s12HJTTY%2Fa%2BbEKj%2B7XQAB%2FgFLDm2i0HYDRc1PCqTYaVdJd%2BBTtI3oUeWQAi7XbnMS6QLH%2B76OH436UmOHpAs%2BcYQZBgo6R2XaSTQxvE6o9t12qKYOsPhk8wwIXW7lp4WQ9inY33nQu6t1zUr9HoGHc9khKqiHFes1eD0RRGhLLy8htDwWNXBDR%2FrrLWxkt%7Ctkp%3ABk9SR_C8qpuDaA
B8: 46240 | C8: Munikis Zero ( Nihil Zero ) M3 Booster Box Sealed Pokemon Card Korean | D8: 37.31 | E8: 0 | F8: Ebay | G8: https://www.ebay.co.uk/itm/287474275860?_skw=Pok%C3%A9mon+Korean+Munikis+booster+box&itmmeta=01M0CVAKR9QS66SQE1T55Q0VEK&hash=item42eecd5614:g:hAcAAeSwR09psZzA&itmprp=enc%3AAQALAAAA4GfYFPkwiKCW4ZNSs2u11xDhufR63EVsNQ2Rx9VdcxjU7IatzaqVoq5MnADiVWG1%2FCyrIEj4xf3z2pXQ1cy06yQ6eyY%2FPL1kR%2B1595Blo2gwc7XcTuVXpZov8DXbmTbN47vZlQ95d2oNBct1Dk2SS29QxPd6o2SqaUM3i8sAJK3dTVR8MxdOkk5ytTh%2BWzDi%2FctUZsGLOpV14cmy7rhmNuFk1KOAJPLZ11wn%2BRVyJztd2fO%2F8KR9DzSy4nO8fg5rS6p%2F1Pv8w0k%2FaX5ZE3V231TcFw0ydez6h4MPf61qOyC%2F%7Ctkp%3ABk9SR_C8qpuDaA
B9: 46241 | C9: Pokémon Korean Munikis / Nihil Zero [M3] Booster Box (30 Packs) | D9: 34.49 | E9: 0 | F9: Ebay | G9: https://www.ebay.co.uk/itm/178383913139?_skw=Pok%C3%A9mon+Korean+Munikis+booster+box&itmmeta=01M0CVAKR9VY8YQF8W09HBAXDA&hash=item29888280b3:g:-6gAAeSwrJFqdk26&itmprp=enc%3AAQALAAABAGfYFPkwiKCW4ZNSs2u11xDRq06oRWd8NO7NxxtIutA95MKgvJwplUdI%2FIOR%2Bt5XdYX4TEunYkyeQOuzjQohNh0Y7V3I2YanWqPY8SXwSNiSqjdyziRBlz8tggW%2FAcVPoL80khBYs7FR6B8buf%2Fo9WZMLVA94emklwafVlMn%2Fi2lbeyoZgo6FTOm3crCsBD3YuRltr4V158xUMFMCBK%2FkudqrxksCQLiub7yD7NRd2kPyse7Xz1I4bTXxxPXyIC7%2F8Dm%2FAX7xFMEBpT1IV1Rfg8egpqGHWEfi88rt8caVG%2BVT5cDUzrkeT9YuKrrnhjKfSdmSjjRymzLlWkbU8R9btI%3D%7Ctkp%3ABk9SR_C8qpuDaA
B10: 46242 | C10: Pokémon Korean Munikis / Nihil Zero [M3] Booster Box (30 Packs) | D10: 36.99 | E10: 0 | F10: Ebay | G10: https://www.ebay.co.uk/itm/336728009466?_skw=Pok%C3%A9mon+Korean+Munikis+booster+box&itmmeta=01M0CVAKR98098Y7B6NX6NJ1ZH&hash=item4e668daafa:g:UXUAAeSw65Bqc2~Y&itmprp=enc%3AAQALAAAA4GfYFPkwiKCW4ZNSs2u11xBHGC2pu2%2BWuVixxpTUmOluSewWntr%2FtCevCzMWInYYz7%2FUvmeVh67tlC783mAn94Ze7NjgGGD4YL07hx50XL6CsXLjOaTAqUBBBsSkURPvDzFfMYJM6BOqL1Mtbt5NLsvz4Oc%2FMKI%2BPOD3g%2F0NClDgVahSGFOxQ8SL0tQAavcIAlKcxQtwXwVjW5560gcH0NhC30RL9m1VQZwqKmKX6ciu8ajZTh0jTemq%2BnlJ%2Fhn9sR0brVdvqHgDLxXD8Ogwz8s%2Bio34j92pc3eZNzrn7PKW%7Ctkp%3ABk9SR_C8qpuDaA
B11: 46243 | C11: Pokémon Korean Munikis / Nihil Zero Booster Box (30 Packs) | D11: 44.99 | E11: 0 | F11: Ebay | G11: https://www.ebay.co.uk/itm/306859714047?_skw=Pok%C3%A9mon+Korean+Munikis+booster+box&itmmeta=01M0CVAKR8T3797J8TK113AHNE&hash=item477243a5ff:g:h0gAAeSwjAVpz--2&itmprp=enc%3AAQALAAABAGfYFPkwiKCW4ZNSs2u11xBXFRXEw%2BMdhLObwP0abaUWTp48DSmZ%2FHzgOWZt36zFBhA9XJpLIbnK1aVoq2KaPYm0kw1Ca%2Fx00OII%2F4ZpLOGZs%2Fp2TgLZiXtEtSz9EeLgT56Kh2Iuzd%2FwVH0SuiDdMEiLiY6F2iNvOwPLWbgOtfqN4vj17GGALg6avQqtWtt9iqVG%2F8fVBycsBpaIYKLbTRNXUjoXiLAQOYMBiuoiMtIqWYPGAB9xyJyOXIl3Kbc4DO4hC2RdkYTugCBXRYdRgz%2FSUPBA8d44r5Z2c0dyQFIUEm0LSMgLKpL9Bht5k1VQW9M0%2Bc3fTLR%2BNeRjBP3rh3Q%3D%7Ctkp%3ABk9SR_C8qpuDaA
B14: Average Sold Price = £41.42
B15: Worst/lowest comp = £34.49

Sheet LEDGER
B2: ITEM | C2: PREDICTED | D2: ACTUAL
B3: eBay Sold Price £ | C3: 41.42 | D3: 41.42
B4: eBay Fee % | C4: 0.1 | D4: 0.13
B5: Postage £ | C5: 0 | D5: 0.44
B6: Import VAT £ | C6: 7.5 | D6: 8.28
B7: Seoul → UK Shipping £ | C7: 14 | D7: 18
B8: FX Cost £ | C8: 0.3 | D8: 0.3
B9: Seoul Shelf Price ₩ | C9: 37776 | D9: 37776
B10: FX Rate ₩/£ | C10: 1800 | D10: 1900
B11: NET REALISABLE | C11: =C3*(1-C4)-C5-C6 -> 29.778 | D11: =D3*(1-D4)-D5-D6 -> 27.3154
B12: TOTAL COST | C12: =C9/C10+C7+C8 -> 35.286667 | D12: =D9/D10+D7+D8 -> 38.182105
B13: MARGIN £ | C13: =C11-C12 -> -5.5086667 | D13: =D11-D12 -> -10.866705
B14: MARGIN % | C14: =C13/C12 -> -0.15611185 | D14: =D13/D12 -> -0.28460205
B15: BREAKEVEN SEOUL PRICE ₩ | C15: 27860.4 | D15: 17129.26
B16: INPUT CHECK | C16: =IF(COUNTBLANK(C3:C10)>0,"ERR — INPUT MISSING","OK") -> OK | D16: =IF(COUNTBLANK(D3:D10)>0,"ERR — INPUT MISSING","OK") -> OK

Sheet Sheet22

Sheet CAMPUS
A1: VENTURE | B1: QUOTED PROFIT £ | C1: TRUE COST £ | D1: HOURS | E1: PROFIT £ | F1: £ PER HOUR | G1: RANK | H1: HONEST | I1: WALL | J1: VERDICT
A2: Car Washing | B2: 200 | C2: 40 | D2: 10 | E2: =IF(OR(NOT(ISNUMBER(B2)),NOT(ISNUMBER(C2))),"ERR",B2-C2) -> 160 | F2: =IF(OR(NOT(ISNUMBER(E2)),NOT(ISNUMBER(D2)),D2=0),"ERR",ROUND(E2/D2,2)) -> 16 | G2: =IF(NOT(ISNUMBER(F2)),"ERR",RANK(F2,$F$2:$F$9,0)) -> 5 | H2: =IF(OR(NOT(ISNUMBER(B2)),NOT(ISNUMBER(C2))),"ERR",B2-C2) -> 160 | I2: Customers pay for convenience; equipment, location and travel make it difficult to offer cheaper washes profitably. | J2: DIG
A3: Tutoring | B3: 200 | C3: 10 | D3: 9 | E3: =IF(OR(NOT(ISNUMBER(B3)),NOT(ISNUMBER(C3))),"ERR",B3-C3) -> 190 | F3: =IF(OR(NOT(ISNUMBER(E3)),NOT(ISNUMBER(D3)),D3=0),"ERR",ROUND(E3/D3,2)) -> 21.11 | G3: =IF(NOT(ISNUMBER(F3)),"ERR",RANK(F3,$F$2:$F$9,0)) -> 3 | H3: =IF(OR(NOT(ISNUMBER(B3)),NOT(ISNUMBER(C3))),"ERR",B3-C3) -> 190 | I3: Parents pay more for trusted tutors; reputation, qualifications and trust make it difficult for new tutors to compete. | J3: DIG
A4: Reselling Clothes | B4: 300 | C4: 170 | D4: 8 | E4: =IF(OR(NOT(ISNUMBER(B4)),NOT(ISNUMBER(C4))),"ERR",B4-C4) -> 130 | F4: =IF(OR(NOT(ISNUMBER(E4)),NOT(ISNUMBER(D4)),D4=0),"ERR",ROUND(E4/D4,2)) -> 16.25 | G4: =IF(NOT(ISNUMBER(F4)),"ERR",RANK(F4,$F$2:$F$9,0)) -> 4 | H4: =IF(OR(NOT(ISNUMBER(B4)),NOT(ISNUMBER(C4))),"ERR",B4-C4) -> 130 | I4: Cheap stock is scattered across marketplaces/charity shops; finding undervalued items takes time and product knowledge. | J4: DIG
A5: Dog Walking | B5: 150 | C5: 15 | D5: 12 | E5: =IF(OR(NOT(ISNUMBER(B5)),NOT(ISNUMBER(C5))),"ERR",B5-C5) -> 135 | F5: =IF(OR(NOT(ISNUMBER(E5)),NOT(ISNUMBER(D5)),D5=0),"ERR",ROUND(E5/D5,2)) -> 11.25 | G5: =IF(NOT(ISNUMBER(F5)),"ERR",RANK(F5,$F$2:$F$9,0)) -> 7 | H5: =IF(OR(NOT(ISNUMBER(B5)),NOT(ISNUMBER(C5))),"ERR",B5-C5) -> 135 | I5: Owners need someone they trust with their pet/home; trust and reputation stop cheaper new competitors entering easily | J5: DROP
A6: Bartender | B6: 140 | C6: 10 | D6: 10 | E6: =IF(OR(NOT(ISNUMBER(B6)),NOT(ISNUMBER(C6))),"ERR",B6-C6) -> 130 | F6: =IF(OR(NOT(ISNUMBER(E6)),NOT(ISNUMBER(D6)),D6=0),"ERR",ROUND(E6/D6,2)) -> 13 | G6: =IF(NOT(ISNUMBER(F6)),"ERR",RANK(F6,$F$2:$F$9,0)) -> 6 | H6: =IF(OR(NOT(ISNUMBER(B6)),NOT(ISNUMBER(C6))),"ERR",B6-C6) -> 130 | I6: Venues control hiring and require reliable/experienced staff; you cannot simply undercut their existing staffing arrangements. | J6: DROP
A7: Social Media Management | B7: 250 | C7: 20 | D7: 10 | E7: =IF(OR(NOT(ISNUMBER(B7)),NOT(ISNUMBER(C7))),"ERR",B7-C7) -> 230 | F7: =IF(OR(NOT(ISNUMBER(E7)),NOT(ISNUMBER(D7)),D7=0),"ERR",ROUND(E7/D7,2)) -> 23 | G7: =IF(NOT(ISNUMBER(F7)),"ERR",RANK(F7,$F$2:$F$9,0)) -> 2 | H7: =IF(OR(NOT(ISNUMBER(B7)),NOT(ISNUMBER(C7))),"ERR",B7-C7) -> 230 | I7: Businesses lack the time and skills to make consistent content; agencies can charge more because switching or doing it in-house takes effort. | J7: DIG
A8: Babysitting | B8: 120 | C8: 10 | D8: 10 | E8: =IF(OR(NOT(ISNUMBER(B8)),NOT(ISNUMBER(C8))),"ERR",B8-C8) -> 110 | F8: =IF(OR(NOT(ISNUMBER(E8)),NOT(ISNUMBER(D8)),D8=0),"ERR",ROUND(E8/D8,2)) -> 11 | G8: =IF(NOT(ISNUMBER(F8)),"ERR",RANK(F8,$F$2:$F$9,0)) -> 8 | H8: =IF(OR(NOT(ISNUMBER(B8)),NOT(ISNUMBER(C8))),"ERR",B8-C8) -> 110 | I8: Parents prioritise trust and recommendations over price; safeguarding and reputation make it hard for unknown cheaper sitters to compete. | J8: DROP
A9: Video Editing | B9: 200 | C9: 15 | D9: 8 | E9: =IF(OR(NOT(ISNUMBER(B9)),NOT(ISNUMBER(C9))),"ERR",B9-C9) -> 185 | F9: =IF(OR(NOT(ISNUMBER(E9)),NOT(ISNUMBER(D9)),D9=0),"ERR",ROUND(E9/D9,2)) -> 23.13 | G9: =IF(NOT(ISNUMBER(F9)),"ERR",RANK(F9,$F$2:$F$9,0)) -> 1 | H9: =IF(OR(NOT(ISNUMBER(B9)),NOT(ISNUMBER(C9))),"ERR",B9-C9) -> 185 | I9: Editing requires time, software and skill; clients pay more because learning it or hiring someone in-house is inconvenient. | J9: DIG

Sheet File_A
A1: PRACTICE FILE — NOT LIVE | G1: PRACTICE FILE — NOT LIVE | M1: `
A2: FILE A — REAL? | G2: FILE B — STALE? | M2: FILE C — EATEN?
A3: Match (invented): Everton v Crystal Palace · The outcome being priced: EVERTON TO WIN | G3: Match (invented): Fulham v Wolves · The outcome being priced: THE DRAW | M3: Match (invented): Sunderland v Brentford · The outcome being priced: SUNDERLAND TO WIN
A4: Invented prices — do not check them against live markets. Everything you need is on this sheet. | G4: Invented prices — do not check them against live markets. Everything you need is on this sheet. | M4: Invented prices — do not check them against live markets. Everything you need is on this sheet.
A6: VENUE | B6: SIDE | C6: PRICE (fraction) | D6: PRICE (decimal) | E6: TAKEN AT | G6: VENUE | H6: SIDE | I6: PRICE (fraction) | J6: PRICE (decimal) | K6: TAKEN AT | M6: VENUE | N6: SIDE | O6: PRICE (fraction) | P6: PRICE (decimal) | Q6: TAKEN AT
A7: Betfred (bookie) | B7: BACK | C7: 46316 | D7: 3.1 | E7: 0.4875 | G7: Bet365 (bookie) | H7: BACK | I7: 14/5 | J7: 3.80 | K7: 13:07 | M7: Bet365 (bookie) | N7: BACK | O7: 31/10 | P7: 4.10 | Q7: 14:03
A8: Smarkets (exchange) | B8: LAY | C8: — | D8: 3 | E8: 0.4875 | G8: Betfair (exchange) | H8: LAY | I8: — | J8: 3.45 | K8: 12:39 | M8: Betfair (exchange) | N8: LAY | O8: — | P8: 4.05 | Q8: 14:03
A9: Exchange commission on winnings: 2% | G9: Exchange commission on winnings: 2% | M9: Exchange commission on winnings: 2%
G10: Wire note, 12:45 — Fulham starting XI announced: first-choice goalkeeper returns from injury.
A11: YOUR WORK — yellow cells only | M11: YOUR WORK — yellow cells only
A12: Back stake (given) | B12: 10 | G12: YOUR WORK — yellow cells only | M12: Back stake (given) | N12: 10
A13: Lay stake — reminder: back stake × back decimal ÷ (lay decimal − commission) | B13: =B12*D7/(D8-0.02) -> 10.402685 | G13: Back stake (given) | H13: 10 | M13: Lay stake — reminder: back stake × back decimal ÷ (lay decimal − commission) | N13: =N12*P7/(P8-0.02) -> 10.173697
G14: Lay stake — reminder: back stake × back decimal ÷ (lay decimal − commission) | H14: =H13*J7/(J8-0.02) -> 11.078717
B15: BOOKIE £ | C15: EXCHANGE £ | D15: NET £ | N15: BOOKIE £ | O15: EXCHANGE £ | P15: NET £
A16: IF EVERTON WIN | B16: =B12*(D7-1) -> 21 | C16: =-B13*(D8-1) -> -20.805369 | D16: =B16+C16 -> 0.19463087 | H16: BOOKIE £ | I16: EXCHANGE £ | J16: NET £ | M16: IF SUNDERLAND WIN | N16: =N12*(P7-1) -> 31 | O16: =-N13*(P8-1) -> -31.029777 | P16: =N16+O16 -> -0.029776675
A17: IF EVERTON DON'T WIN | B17: =-B12 -> -10 | C17: =B13*(1-0.02) -> 10.194631 | D17: =B17+C17 -> 0.19463087 | G17: IF IT'S A DRAW | H17: =H13*(J7-1) -> 28 | I17: =-H14*(J8-1) -> -27.142857 | J17: =H17+I17 -> 0.85714286 | M17: IF THEY DON'T | N17: =-N12 -> -10 | O17: =N13*(1-0.02) -> 9.9702233 | P17: =N17+O17 -> -0.029776675
A18: Money you pay out goes in as a minus, e.g. -0.35 for a 35p loss. | G18: IF IT ISN'T | H18: =-H13 -> -10 | I18: =H14*(1-0.02) -> 10.857143 | J18: =H18+I18 -> 0.85714286 | M18: Money you pay out goes in as a minus, e.g. -0.35 for a 35p loss.
G19: Money you pay out goes in as a minus, e.g. -0.35 for a 35p loss.
A20: VERDICT (REAL / STALE / EATEN) | B20: REAL | M20: NET per side if commission were 0% | N20: 0.12
A21: ONE LINE OF PROOF | B21: Both prices were taken at 11:42 and both outcomes make a profit after 2% commission. | G21: VERDICT (REAL / STALE / EATEN) | H21: STALE | M21: NET per side at the real 2% | N21: -0.03
G22: ONE LINE OF PROOF | H22: The lay price was taken at 12:39 before the 12:45 team news, while the back price was taken at 13:07 after the news. | M22: Same trade at £100 stakes — NET | N22: -0.3
A23: Then post the verdict + proof line in #trading-floor. 5 points a file.
G24: Then post the verdict + proof line in #trading-floor. 5 points a file. | M24: VERDICT (REAL / STALE / EATEN) | N24: EATEN
M25: ONE LINE OF PROOF | N25: Without commission the trade makes about £0.12 per side, but the real 2% commission turns it into about a £0.03 loss per side.
M27: Then post the verdict + proof line in #trading-floor. 5 points a file.

Sheet RADAR
A1: FALSE | B1: LIVE Wed 10:38 | D1: COMMISSION | E1: 0.05 | F1: LEAGUE | G1: La Liga
A3: MATCH | B3: OUTCOME | C3: BEST | D3: WHERE | E3: BACK | F3: LAY | G3: GAP | H3: RATING | I3: VERDICT
A4: Real Madrid v Real Sociedad | B4: Real Madrid | C4: 1.26 | D4: Grosvenor | E4: 1.3 | F4: 1.31 | G4: =IF(OR($C4="",$C4=0,$F4=""),"",$C4/$F4-1) -> -0.038167939 | H4: =IF($G4="","",($C4*(1-$E$1))/($F4-$E$1)) -> 0.95 | I4: =IF($H4="","",IF($H4>1,"LOOK","NO")) -> NO
A5: Real Madrid v Real Sociedad | B5: Draw | C5: 6.5 | D5: LeoVegas | E5: 6.6 | F5: 6.8 | G5: =IF(OR($C5="",$C5=0,$F5=""),"",$C5/$F5-1) -> -0.044117647 | H5: =IF($G5="","",($C5*(1-$E$1))/($F5-$E$1)) -> 0.91481481 | I5: =IF($H5="","",IF($H5>1,"LOOK","NO")) -> NO
A6: Real Madrid v Real Sociedad | B6: Real Sociedad | C6: 11 | D6: Betfred (UK) | E6: 12 | F6: 12.5 | G6: =IF(OR($C6="",$C6=0,$F6=""),"",$C6/$F6-1) -> -0.12 | H6: =IF($G6="","",($C6*(1-$E$1))/($F6-$E$1)) -> 0.83935743 | I6: =IF($H6="","",IF($H6>1,"LOOK","NO")) -> NO
A7: Celta Vigo v CA Osasuna | B7: Celta Vigo | C7: 2 | D7: Grosvenor | E7: 2.04 | F7: 2.08 | G7: =IF(OR($C7="",$C7=0,$F7=""),"",$C7/$F7-1) -> -0.038461538 | H7: =IF($G7="","",($C7*(1-$E$1))/($F7-$E$1)) -> 0.93596059 | I7: =IF($H7="","",IF($H7>1,"LOOK","NO")) -> NO
A8: Celta Vigo v CA Osasuna | B8: Draw | C8: 3.4 | D8: Grosvenor | E8: 3.5 | F8: 3.55 | G8: =IF(OR($C8="",$C8=0,$F8=""),"",$C8/$F8-1) -> -0.042253521 | H8: =IF($G8="","",($C8*(1-$E$1))/($F8-$E$1)) -> 0.92285714 | I8: =IF($H8="","",IF($H8>1,"LOOK","NO")) -> NO
A9: Celta Vigo v CA Osasuna | B9: CA Osasuna | C9: 4.2 | D9: Coral | E9: 4.3 | F9: 4.4 | G9: =IF(OR($C9="",$C9=0,$F9=""),"",$C9/$F9-1) -> -0.045454545 | H9: =IF($G9="","",($C9*(1-$E$1))/($F9-$E$1)) -> 0.91724138 | I9: =IF($H9="","",IF($H9>1,"LOOK","NO")) -> NO
A10: Barcelona v Athletic Bilbao | B10: Barcelona | C10: 1.35 | D10: Coral | E10: 1.34 | F10: 1.35 | G10: =IF(OR($C10="",$C10=0,$F10=""),"",$C10/$F10-1) -> 0 | H10: =IF($G10="","",($C10*(1-$E$1))/($F10-$E$1)) -> 0.98653846 | I10: =IF($H10="","",IF($H10>1,"LOOK","NO")) -> NO
A11: Barcelona v Athletic Bilbao | B11: Draw | C11: 6.1 | D11: Grosvenor | E11: 6.4 | F11: 6.6 | G11: =IF(OR($C11="",$C11=0,$F11=""),"",$C11/$F11-1) -> -0.075757576 | H11: =IF($G11="","",($C11*(1-$E$1))/($F11-$E$1)) -> 0.88473282 | I11: =IF($H11="","",IF($H11>1,"LOOK","NO")) -> NO
A12: Barcelona v Athletic Bilbao | B12: Athletic Bilbao | C12: 9.5 | D12: Grosvenor | E12: 10 | F12: 10.5 | G12: =IF(OR($C12="",$C12=0,$F12=""),"",$C12/$F12-1) -> -0.095238095 | H12: =IF($G12="","",($C12*(1-$E$1))/($F12-$E$1)) -> 0.86363636 | I12: =IF($H12="","",IF($H12>1,"LOOK","NO")) -> NO
A13: Real Racing Club de Santander v Elche CF | B13: Real Racing Club de Santander | C13: 2.2 | D13: Ladbrokes | E13: 2.22 | F13: 2.26 | G13: =IF(OR($C13="",$C13=0,$F13=""),"",$C13/$F13-1) -> -0.026548673 | H13: =IF($G13="","",($C13*(1-$E$1))/($F13-$E$1)) -> 0.94570136 | I13: =IF($H13="","",IF($H13>1,"LOOK","NO")) -> NO
A14: Real Racing Club de Santander v Elche CF | B14: Draw | C14: 3.6 | D14: Betfred (UK) | E14: 3.6 | F14: 3.7 | G14: =IF(OR($C14="",$C14=0,$F14=""),"",$C14/$F14-1) -> -0.027027027 | H14: =IF($G14="","",($C14*(1-$E$1))/($F14-$E$1)) -> 0.9369863 | I14: =IF($H14="","",IF($H14>1,"LOOK","NO")) -> NO
A15: Real Racing Club de Santander v Elche CF | B15: Elche CF | C15: 3.5 | D15: Grosvenor | E15: 3.5 | F15: 3.65 | G15: =IF(OR($C15="",$C15=0,$F15=""),"",$C15/$F15-1) -> -0.04109589 | H15: =IF($G15="","",($C15*(1-$E$1))/($F15-$E$1)) -> 0.92361111 | I15: =IF($H15="","",IF($H15>1,"LOOK","NO")) -> NO
... A42: Barcelona v Rayo Vallecano | B42: Rayo Vallecano | C42: 13 | D42: Paddy Power | E42: 13 | F42: 15 | G42: =IF(OR($C42="",$C42=0,$F42=""),"",$C42/$F42-1) -> -0.13333333 | H42: =IF($G42="","",($C42*(1-$E$1))/($F42-$E$1)) -> 0.82608696 | I42: =IF($H42="","",IF($H42>1,"LOOK","NO")) -> NO
G43: =IF(OR($C43="",$C43=0,$F43=""),"",$C43/$F43-1) | H43: =IF($G43="","",($C43*(1-$E$1))/($F43-$E$1)) | I43: =IF($H43="","",IF($H43>1,"LOOK","NO"))
G44: =IF(OR($C44="",$C44=0,$F44=""),"",$C44/$F44-1) | H44: =IF($G44="","",($C44*(1-$E$1))/($F44-$E$1)) | I44: =IF($H44="","",IF($H44>1,"LOOK","NO"))
G45: =IF(OR($C45="",$C45=0,$F45=""),"",$C45/$F45-1) | H45: =IF($G45="","",($C45*(1-$E$1))/($F45-$E$1)) | I45: =IF($H45="","",IF($H45>1,"LOOK","NO"))
G46: =IF(OR($C46="",$C46=0,$F46=""),"",$C46/$F46-1) | H46: =IF($G46="","",($C46*(1-$E$1))/($F46-$E$1)) | I46: =IF($H46="","",IF($H46>1,"LOOK","NO"))
G47: =IF(OR($C47="",$C47=0,$F47=""),"",$C47/$F47-1) | H47: =IF($G47="","",($C47*(1-$E$1))/($F47-$E$1)) | I47: =IF($H47="","",IF($H47>1,"LOOK","NO"))
G48: =IF(OR($C48="",$C48=0,$F48=""),"",$C48/$F48-1) | H48: =IF($G48="","",($C48*(1-$E$1))/($F48-$E$1)) | I48: =IF($H48="","",IF($H48>1,"LOOK","NO"))
G49: =IF(OR($C49="",$C49=0,$F49=""),"",$C49/$F49-1) | H49: =IF($G49="","",($C49*(1-$E$1))/($F49-$E$1)) | I49: =IF($H49="","",IF($H49>1,"LOOK","NO"))
G50: =IF(OR($C50="",$C50=0,$F50=""),"",$C50/$F50-1) | H50: =IF($G50="","",($C50*(1-$E$1))/($F50-$E$1)) | I50: =IF($H50="","",IF($H50>1,"LOOK","NO"))
G51: =IF(OR($C51="",$C51=0,$F51=""),"",$C51/$F51-1) | H51: =IF($G51="","",($C51*(1-$E$1))/($F51-$E$1)) | I51: =IF($H51="","",IF($H51>1,"LOOK","NO"))
G52: =IF(OR($C52="",$C52=0,$F52=""),"",$C52/$F52-1) | H52: =IF($G52="","",($C52*(1-$E$1))/($F52-$E$1)) | I52: =IF($H52="","",IF($H52>1,"LOOK","NO"))
G53: =IF(OR($C53="",$C53=0,$F53=""),"",$C53/$F53-1) | H53: =IF($G53="","",($C53*(1-$E$1))/($F53-$E$1)) | I53: =IF($H53="","",IF($H53>1,"LOOK","NO"))
G54: =IF(OR($C54="",$C54=0,$F54=""),"",$C54/$F54-1) | H54: =IF($G54="","",($C54*(1-$E$1))/($F54-$E$1)) | I54: =IF($H54="","",IF($H54>1,"LOOK","NO"))
... G63: =IF(OR($C63="",$C63=0,$F63=""),"",$C63/$F63-1) | H63: =IF($G63="","",($C63*(1-$E$1))/($F63-$E$1)) | I63: =IF($H63="","",IF($H63>1,"LOOK","NO"))
A501: Dallas Cowboys v Philadelphia Eagles | B501: Philadelphia Eagles | C501: 2.04 | D501: Unibet (UK)
A502: Buffalo Bills v Kansas City Chiefs | B502: Buffalo Bills | C502: 1.65 | D502: Unibet (UK)
A503: Buffalo Bills v Kansas City Chiefs | B503: Draw | C503: 0
A504: Buffalo Bills v Kansas City Chiefs | B504: Kansas City Chiefs | C504: 2.25 | D504: Paddy Power
A505: Pittsburgh Steelers v Denver Broncos | B505: Pittsburgh Steelers | C505: 2.1 | D505: Paddy Power
A506: Pittsburgh Steelers v Denver Broncos | B506: Draw | C506: 0
A507: Pittsburgh Steelers v Denver Broncos | B507: Denver Broncos | C507: 1.73 | D507: Paddy Power
A508: Minnesota Vikings v Atlanta Falcons | B508: Minnesota Vikings | C508: 0
A509: Minnesota Vikings v Atlanta Falcons | B509: Draw | C509: 0
A510: Minnesota Vikings v Atlanta Falcons | B510: Atlanta Falcons | C510: 0
A511: Houston Texans v Baltimore Ravens | B511: Houston Texans | C511: 0
A512: Houston Texans v Baltimore Ravens | B512: Draw | C512: 0
...

Sheet LOG
A1: DATE | B1: MATCH + OUTCOME | C1: GAP | D1: RATING | E1: YOUR CALL | F1: PRICE AT KICK OFF | G1: RIGHT?

Sheet CARD
A1: IDEA | B1: STATUS | C1: KILLING FILTER
A2: DEADLINE — A one-screen tool that shows me exactly what uni work I need to do next, based on urgency and deadline | B2: SURVIVED
A3: MATCHDAY — A one-screen matchday tool that tells me the one football match most worth watching today and why. | B3: KILLED | C3: Problem — not a strong enough problem I actually have
A4: SPLIT — A one-screen tool for nights out that lets me enter a bill and instantly shows exactly what each mate owes. | B4: KILLED | C4: One action — splitting different bills can quickly require multiple inputs/actions
A7: PRODUCT CARD - DEADLINE
A9: WHAT IT DOES | B9: A one-screen tool that tells me which piece of uni work I should do next based on its deadline and urgency.
A10: THE MOMENT | B10: A student opens it when they sit down to work and don't know which assignment or task to start first.
A11: WHAT PEOPLE DO NOW | B11: Check different course pages, calendars and notes, then decide manually what is most urgent.
A12: THE 30 SECOND DEMO | B12: Enter my current assignments and deadlines → press one button → the tool shows the task I should work on next.
A13: VERSION 1 | B13: Enter tasks and deadlines, then rank them by urgency and show the highest-priority task.
A14: DONE WHEN | B14: Tasks can be entered; deadlines are accepted; one action ranks them; the most urgent task is clearly shown; missing/invalid information produces a clear error.
A17: PITCH
A18: VERDICT | B18: FUND
A19: TARGET DATE | B19: 46266
A20: WHAT WILL EXIST | B20: A working one-screen version of DEADLINE where I can enter tasks and deadlines, press one button, and it clearly shows me the most urgent task to work on next. Missing or invalid information will show a clear error.

Sheet DEADLINE (starter
A1: DEADLINE | B1: RANKED Wed 11:08 | F1: WHAT SHOULD I DO NEXT
A3: TASK | B3: DEADLINE | C3: URGENCY | D3: STATUS | F3: NEXT TASK
A4: SUBMIT PRESENTATION | B4: 46260 | C4: HIGH | D4: NOT DONE | F4: =IFERROR(__xludf.DUMMYFUNCTION("IFERROR(INDEX(SORT(FILTER({A4:A100,B4:B100,IF(C4:C100=""HIGH"",1,IF(C4:C100=""MEDIUM"",2,3))},A4:A100<>"""",D4:D100<>""DONE""),3,TRUE,2,TRUE),1,1),""NO TASKS"")"),"SUBMIT PRESENTATION") -> SUBMIT PRESENTATION
A5: FINISH ESSAY | B5: 46262 | C5: MEDIUM | D5: NOT DONE
A6: REVISE BUSINESS | B6: 46264 | C6: HIGH | D6: NOT DONE | F6: STATUS
F7: =IF(COUNTA(A4:A100)=0,"NO TASKS",IF(COUNTIFS(A4:A100,"<>",B4:B100,"")+COUNTIFS(A4:A100,"<>",C4:C100,"")+COUNTIFS(A4:A100,"<>",D4:D100,"")>0,"MISSING INFORMATION","READY")) -> READY

Sheet DEADLINE
A1: FALSE | B1: RANKED Wed 11:17
A2: {=IF(COUNTA(A4:A100)=0,"ADD A TASK BELOW",IF(COUNTIF(D4:D100,"NO DATE")>0,"FIX THE RED ROW FIRST","DO NEXT → "&INDEX(A4:A100,MATCH(MIN(B4:B100),B4:B100,0))))} -> DO NEXT → Submit Seminar reflection
A3: TASK | B3: DUE | C3: DAYS LEFT | D3: STATUS
A4: Submit Seminar reflection | B4: 46261 | C4: =IF($A4="","",IF(NOT(ISNUMBER($B4)),"ERR",$B4-TODAY())) -> -4 | D4: =IF($A4="","",IF(NOT(ISNUMBER($B4)),"NO DATE",IF($B4<TODAY(),"OVERDUE",IF($B4=TODAY(),"DUE TODAY","OK")))) -> OVERDUE
A5: Speak to tutor about Extra Time | B5: 46262 | C5: =IF($A5="","",IF(NOT(ISNUMBER($B5)),"ERR",$B5-TODAY())) -> -3 | D5: =IF($A5="","",IF(NOT(ISNUMBER($B5)),"NO DATE",IF($B5<TODAY(),"OVERDUE",IF($B5=TODAY(),"DUE TODAY","OK")))) -> OVERDUE
A6: Make accounting formula flashcards | B6: 46263 | C6: =IF($A6="","",IF(NOT(ISNUMBER($B6)),"ERR",$B6-TODAY())) -> -2 | D6: =IF($A6="","",IF(NOT(ISNUMBER($B6)),"NO DATE",IF($B6<TODAY(),"OVERDUE",IF($B6=TODAY(),"DUE TODAY","OK")))) -> OVERDUE
A7: Complete Business Ethics quiz | B7: 46265 | C7: =IF($A7="","",IF(NOT(ISNUMBER($B7)),"ERR",$B7-TODAY())) -> 0 | D7: =IF($A7="","",IF(NOT(ISNUMBER($B7)),"NO DATE",IF($B7<TODAY(),"OVERDUE",IF($B7=TODAY(),"DUE TODAY","OK")))) -> DUE TODAY
A8: prepare questions for marketing seminar | B8: 46267 | C8: =IF($A8="","",IF(NOT(ISNUMBER($B8)),"ERR",$B8-TODAY())) -> 2 | D8: =IF($A8="","",IF(NOT(ISNUMBER($B8)),"NO DATE",IF($B8<TODAY(),"OVERDUE",IF($B8=TODAY(),"DUE TODAY","OK")))) -> OK
A9: Qualitative Analysis revision for exam | B9: 46269 | C9: =IF($A9="","",IF(NOT(ISNUMBER($B9)),"ERR",$B9-TODAY())) -> 4 | D9: =IF($A9="","",IF(NOT(ISNUMBER($B9)),"NO DATE",IF($B9<TODAY(),"OVERDUE",IF($B9=TODAY(),"DUE TODAY","OK")))) -> OK
A10: Work and Society group presentation | B10: 46276 | C10: =IF($A10="","",IF(NOT(ISNUMBER($B10)),"ERR",$B10-TODAY())) -> 11 | D10: =IF($A10="","",IF(NOT(ISNUMBER($B10)),"NO DATE",IF($B10<TODAY(),"OVERDUE",IF($B10=TODAY(),"DUE TODAY","OK")))) -> OK
A11: Business Economics Coursework | B11: 46283 | C11: =IF($A11="","",IF(NOT(ISNUMBER($B11)),"ERR",$B11-TODAY())) -> 18 | D11: =IF($A11="","",IF(NOT(ISNUMBER($B11)),"NO DATE",IF($B11<TODAY(),"OVERDUE",IF($B11=TODAY(),"DUE TODAY","OK")))) -> OK

Sheet COMPASS
A1: COMPASS
A2: WHAT SHOULD I AIM FOR NEXT?
A3: 🎯 DO NOW | B3: {=IFERROR(INDEX($A$11:$A$100,MATCH(1,$N$11:$N$100,0)),"ADD GOALS")} -> Go to the gym 4x a week
A4: 🔥 MOST WANTED | B4: {=IFERROR(INDEX($A$11:$A$100,MATCH(1,$T$11:$T$100,0)),"ADD GOALS")} -> Travel to Australia | D4: 💰 CURRENT FUNDS | E4: 350
A5: 📅 BEST IN 1 YEAR | B5: {=IFERROR(INDEX($A$11:$A$100,MATCH(1,$U$11:$U$100,0)),"ADD GOALS")} -> Go to the gym 4x a week | D5: 💵 MONTHLY INCOME | E5: 50
A6: 🚀 BEST IN 3 YEARS | B6: {=IFERROR(INDEX($A$11:$A$100,MATCH(1,$V$11:$V$100,0)),"ADD GOALS")} -> Go to the gym 4x a week | D6: 💸 MONTHLY SPARE MONEY | E6: 70
A7: QUICK WIN | B7: =IFERROR(__xludf.DUMMYFUNCTION("IFERROR(INDEX($A$11:$A$100,MATCH(MAX(FILTER($F$11:$F$100+$J$11:$J$100,$D$11:$D$100<=MAX(0,$E$4-$E$8))),FILTER($F$11:$F$100+$J$11:$J$100,$D$11:$D$100<=MAX(0,$E$4-$E$8)),0)),""NONE YET"")"),"Look into USA semester/term abroad for 3rd year") -> Look into USA semester/term abroad for 3rd year | D7: ⏰ FREE HOURS / WEEK | E7: 40
D8: 🛟 CASH BUFFER | E8: 50
A10: GOAL | B10: CATEGORY | C10: TIMEFRAME | D10: COST £ | E10: HOURS/WEEK | F10: WANT /10 | G10: MONEY /10 | H10: TIME /10 | I10: DIFFICULTY /10 | J10: NOW /10 | K10: 1 YEAR /10 | L10: 3 YEARS /10 | M10: PRIORITY | N10: RANK | O10: VERDICT | P10: BLOCKER | Q10: NEXT MOVE | R10: FUNDING GAP | S10: Months to Afford | T10: WANT RANK | U10: 1 YEAR PRIORITY | V10: 3 YEAR PRIORITY
A11: Travel to Australia | B11: Travel | C11: 1-3 YEARS | D11: 7000 | E11: 1 | F11: 10 | G11: =IF(A11="","",IF(D11<=0,10,ROUND(MAX(1,MIN(10,(MAX(0,$E$4-$E$8)/D11)*10)),1))) -> 1 | H11: =IF(A11="","",IF(E11<=0,10,ROUND(MAX(1,MIN(10,10-(E11/MAX(1,$E$7)*10))),1))) -> 9.8 | I11: =IF(A11="","",ROUND(MIN(10,MAX(1, ((11-G11)*0.45)+ ((11-H11)*0.25)+ (MIN(10,E11/2)*0.2)+ (IF(C11="NOW",1,IF(C11="THIS YEAR",2,IF(C11="1 YEAR",3,IF(C11="1-3 YEARS",5,IF(C11="3 YEARS",7,6)))))*0.1) )),1)) -> 5.4 | J11: =IF(A11="","",ROUND((G11*0.4)+(H11*0.3)+((11-I11)*0.3),1)) -> 5 | K11: =IF(A11="","",ROUND( (MAX(1,MIN(10,IF(D11<=0,10,(MAX(0,$E$4-$E$8)+($E$6*12))/D11*10)))*0.4) + (MIN(10,H11+0.5)*0.3) + (MIN(10,12-I11)*0.3) ,1)) -> 5.6 | L11: =IF(A11="","",ROUND( (MAX(1,MIN(10,IF(D11<=0,10,(MAX(0,$E$4-$E$8)+($E$6*36))/D11*10)))*0.4) + (MIN(10,H11+1.5)*0.3) + (MIN(10,14-I11)*0.3) ,1)) -> 7.2 | M11: =IF(A11="","",ROUND((F11*0.45)+(J11*0.4)+((11-I11)*0.15),2)) -> 7.34 | N11: =IFERROR(__xludf.DUMMYFUNCTION("IF(A11="""","""",RANK(M11,FILTER($M$11:$M$100,$A$11:$A$100<>""""),0))"),18.0) -> 18 | O11: =IF(A11="","",IF(AND(F11>=8,J11<4),"DREAM",IF(J11>=8,"DO NOW",IF(J11>=6,"START PLANNING",IF(K11>=7,"BUILD TOWARDS","PARK"))))) -> PARK | P11: =IF(A11="","",IF(J11>=9,"NONE",IF(G11<=H11,IF(G11<=11-I11,"MONEY","DIFFICULTY"),IF(H11<=11-I11,"TIME","DIFFICULTY")))) -> MONEY | R11: =IF(A11="","",MAX(0,D11-MAX(0,$E$4-$E$8))) -> 6700 | S11: =IF(A11="","",IF(R11=0,0,IF($E$6<=0,"NO SAVINGS",ROUNDUP(R11/$E$6,0)))) -> 96 | T11: =IFERROR(__xludf.DUMMYFUNCTION("IF(A11="""","""",RANK(F11,FILTER($F$11:$F$100,$A$11:$A$100<>""""),0))"),1.0) -> 1 | U11: =IFERROR(__xludf.DUMMYFUNCTION("IF(A11="""","""",RANK( (F11*0.5+K11*0.5), FILTER($F$11:$F$100*0.5+$K$11:$K$100*0.5,$A$11:$A$100<>""""), 0))"),16.0) -> 16 | V11: =IFERROR(__xludf.DUMMYFUNCTION("IF(A11="""","""",RANK( (F11*0.65+L11*0.35), FILTER($F$11:$F$100*0.65+$L$11:$L$100*0.35,$A$11:$A$100<>""""), 0))"),6.0) -> 6
A12: Play tennis once a week | B12: Hobby | C12: NOW | D12: 0 | E12: 2 | F12: 7 | G12: =IF(A12="","",IF(D12<=0,10,ROUND(MAX(1,MIN(10,(MAX(0,$E$4-$E$8)/D12)*10)),1))) -> 10 | H12: =IF(A12="","",IF(E12<=0,10,ROUND(MAX(1,MIN(10,10-(E12/MAX(1,$E$7)*10))),1))) -> 9.5 | I12: =IF(A12="","",ROUND(MIN(10,MAX(1, ((11-G12)*0.45)+ ((11-H12)*0.25)+ (MIN(10,E12/2)*0.2)+ (IF(C12="NOW",1,IF(C12="THIS YEAR",2,IF(C12="1 YEAR",3,IF(C12="1-3 YEARS",5,IF(C12="3 YEARS",7,6)))))*0.1) )),1)) -> 1.1 | J12: =IF(A12="","",ROUND((G12*0.4)+(H12*0.3)+((11-I12)*0.3),1)) -> 9.8 | K12: =IF(A12="","",ROUND( (MAX(1,MIN(10,IF(D12<=0,10,(MAX(0,$E$4-$E$8)+($E$6*12))/D12*10)))*0.4) + (MIN(10,H12+0.5)*0.3) + (MIN(10,12-I12)*0.3) ,1)) -> 10 | L12: =IF(A12="","",ROUND( (MAX(1,MIN(10,IF(D12<=0,10,(MAX(0,$E$4-$E$8)+($E$6*36))/D12*10)))*0.4) + (MIN(10,H12+1.5)*0.3) + (MIN(10,14-I12)*0.3) ,1)) -> 10 | M12: =IF(A12="","",ROUND((F12*0.45)+(J12*0.4)+((11-I12)*0.15),2)) -> 8.56 | N12: =IFERROR(__xludf.DUMMYFUNCTION("IF(A12="""","""",RANK(M12,FILTER($M$11:$M$100,$A$11:$A$100<>""""),0))"),8.0) -> 8 | O12: =IF(A12="","",IF(AND(F12>=8,J12<4),"DREAM",IF(J12>=8,"DO NOW",IF(J12>=6,"START PLANNING",IF(K12>=7,"BUILD TOWARDS","PARK"))))) -> DO NOW | P12: =IF(A12="","",IF(J12>=9,"NONE",IF(G12<=H12,IF(G12<=11-I12,"MONEY","DIFFICULTY"),IF(H12<=11-I12,"TIME","DIFFICULTY")))) -> NONE | R12: =IF(A12="","",MAX(0,D12-MAX(0,$E$4-$E$8))) -> 0 | S12: =IF(A12="","",IF(R12=0,0,IF($E$6<=0,"NO SAVINGS",ROUNDUP(R12/$E$6,0)))) -> 0 | T12: =IFERROR(__xludf.DUMMYFUNCTION("IF(A12="""","""",RANK(F12,FILTER($F$11:$F$100,$A$11:$A$100<>""""),0))"),9.0) -> 9 | U12: =IFERROR(__xludf.DUMMYFUNCTION("IF(A12="""","""",RANK( (F12*0.5+K12*0.5), FILTER($F$11:$F$100*0.5+$K$11:$K$100*0.5,$A$11:$A$100<>""""), 0))"),7.0) -> 7 | V12: =IFERROR(__xludf.DUMMYFUNCTION("IF(A12="""","""",RANK( (F12*0.65+L12*0.35), FILTER($F$11:$F$100*0.65+$L$11:$L$100*0.35,$A$11:$A$100<>""""), 0))"),9.0) -> 9
A13: Get a First in university second year | B13: University | C13: THIS YEAR | D13: 0 | E13: 12 | F13: 10 | G13: =IF(A13="","",IF(D13<=0,10,ROUND(MAX(1,MIN(10,(MAX(0,$E$4-$E$8)/D13)*10)),1))) -> 10 | H13: =IF(A13="","",IF(E13<=0,10,ROUND(MAX(1,MIN(10,10-(E13/MAX(1,$E$7)*10))),1))) -> 7 | I13: =IF(A13="","",ROUND(MIN(10,MAX(1, ((11-G13)*0.45)+ ((11-H13)*0.25)+ (MIN(10,E13/2)*0.2)+ (IF(C13="NOW",1,IF(C13="THIS YEAR",2,IF(C13="1 YEAR",3,IF(C13="1-3 YEARS",5,IF(C13="3 YEARS",7,6)))))*0.1) )),1)) -> 2.9 | J13: =IF(A13="","",ROUND((G13*0.4)+(H13*0.3)+((11-I13)*0.3),1)) -> 8.5 | K13: =IF(A13="","",ROUND( (MAX(1,MIN(10,IF(D13<=0,10,(MAX(0,$E$4-$E$8)+($E$6*12))/D13*10)))*0.4) + (MIN(10,H13+0.5)*0.3) + (MIN(10,12-I13)*0.3) ,1)) -> 9 | L13: =IF(A13="","",ROUND( (MAX(1,MIN(10,IF(D13<=0,10,(MAX(0,$E$4-$E$8)+($E$6*36))/D13*10)))*0.4) + (MIN(10,H13+1.5)*0.3) + (MIN(10,14-I13)*0.3) ,1)) -> 9.6 | M13: =IF(A13="","",ROUND((F13*0.45)+(J13*0.4)+((11-I13)*0.15),2)) -> 9.12 | N13: =IFERROR(__xludf.DUMMYFUNCTION("IF(A13="""","""",RANK(M13,FILTER($M$11:$M$100,$A$11:$A$100<>""""),0))"),3.0) -> 3 | O13: =IF(A13="","",IF(AND(F13>=8,J13<4),"DREAM",IF(J13>=8,"DO NOW",IF(J13>=6,"START PLANNING",IF(K13>=7,"BUILD TOWARDS","PARK"))))) -> DO NOW | P13: =IF(A13="","",IF(J13>=9,"NONE",IF(G13<=H13,IF(G13<=11-I13,"MONEY","DIFFICULTY"),IF(H13<=11-I13,"TIME","DIFFICULTY")))) -> TIME | R13: =IF(A13="","",MAX(0,D13-MAX(0,$E$4-$E$8))) -> 0 | S13: =IF(A13="","",IF(R13=0,0,IF($E$6<=0,"NO SAVINGS",ROUNDUP(R13/$E$6,0)))) -> 0 | T13: =IFERROR(__xludf.DUMMYFUNCTION("IF(A13="""","""",RANK(F13,FILTER($F$11:$F$100,$A$11:$A$100<>""""),0))"),1.0) -> 1 | U13: =IFERROR(__xludf.DUMMYFUNCTION("IF(A13="""","""",RANK( (F13*0.5+K13*0.5), FILTER($F$11:$F$100*0.5+$K$11:$K$100*0.5,$A$11:$A$100<>""""), 0))"),2.0) -> 2 | V13: =IFERROR(__xludf.DUMMYFUNCTION("IF(A13="""","""",RANK( (F13*0.65+L13*0.35), FILTER($F$11:$F$100*0.65+$L$11:$L$100*0.35,$A$11:$A$100<>""""), 0))"),2.0) -> 2
A14: Save £2000 | B14: Money | C14: 1 YEAR | D14: 0 | E14: 0 | F14: 8 | G14: =IF(A14="","",IF(D14<=0,10,ROUND(MAX(1,MIN(10,(MAX(0,$E$4-$E$8)/D14)*10)),1))) -> 10 | H14: =IF(A14="","",IF(E14<=0,10,ROUND(MAX(1,MIN(10,10-(E14/MAX(1,$E$7)*10))),1))) -> 10 | I14: =IF(A14="","",ROUND(MIN(10,MAX(1, ((11-G14)*0.45)+ ((11-H14)*0.25)+ (MIN(10,E14/2)*0.2)+ (IF(C14="NOW",1,IF(C14="THIS YEAR",2,IF(C14="1 YEAR",3,IF(C14="1-3 YEARS",5,IF(C14="3 YEARS",7,6)))))*0.1) )),1)) -> 1 | J14: =IF(A14="","",ROUND((G14*0.4)+(H14*0.3)+((11-I14)*0.3),1)) -> 10 | K14: =IF(A14="","",ROUND( (MAX(1,MIN(10,IF(D14<=0,10,(MAX(0,$E$4-$E$8)+($E$6*12))/D14*10)))*0.4) + (MIN(10,H14+0.5)*0.3) + (MIN(10,12-I14)*0.3) ,1)) -> 10 | L14: =IF(A14="","",ROUND( (MAX(1,MIN(10,IF(D14<=0,10,(MAX(0,$E$4-$E$8)+($E$6*36))/D14*10)))*0.4) + (MIN(10,H14+1.5)*0.3) + (MIN(10,14-I14)*0.3) ,1)) -> 10 | M14: =IF(A14="","",ROUND((F14*0.45)+(J14*0.4)+((11-I14)*0.15),2)) -> 9.1 | N14: =IFERROR(__xludf.DUMMYFUNCTION("IF(A14="""","""",RANK(M14,FILTER($M$11:$M$100,$A$11:$A$100<>""""),0))"),4.0) -> 4 | O14: =IF(A14="","",IF(AND(F14>=8,J14<4),"DREAM",IF(J14>=8,"DO NOW",IF(J14>=6,"START PLANNING",IF(K14>=7,"BUILD TOWARDS","PARK"))))) -> DO NOW | P14: =IF(A14="","",IF(J14>=9,"NONE",IF(G14<=H14,IF(G14<=11-I14,"MONEY","DIFFICULTY"),IF(H14<=11-I14,"TIME","DIFFICULTY")))) -> NONE | R14: =IF(A14="","",MAX(0,D14-MAX(0,$E$4-$E$8))) -> 0 | S14: =IF(A14="","",IF(R14=0,0,IF($E$6<=0,"NO SAVINGS",ROUNDUP(R14/$E$6,0)))) -> 0 | T14: =IFERROR(__xludf.DUMMYFUNCTION("IF(A14="""","""",RANK(F14,FILTER($F$11:$F$100,$A$11:$A$100<>""""),0))"),7.0) -> 7 | U14: =IFERROR(__xludf.DUMMYFUNCTION("IF(A14="""","""",RANK( (F14*0.5+K14*0.5), FILTER($F$11:$F$100*0.5+$K$11:$K$100*0.5,$A$11:$A$100<>""""), 0))"),4.0) -> 4 | V14: =IFERROR(__xludf.DUMMYFUNCTION("IF(A14="""","""",RANK( (F14*0.65+L14*0.35), FILTER($F$11:$F$100*0.65+$L$11:$L$100*0.35,$A$11:$A$100<>""""), 0))"),7.0) -> 7
A15: Start at least 2 shifts a week at Univeristy (JOB) | B15: Career | C15: THIS YEAR | D15: 100 | E15: 18 | F15: 9 | G15: =IF(A15="","",IF(D15<=0,10,ROUND(MAX(1,MIN(10,(MAX(0,$E$4-$E$8)/D15)*10)),1))) -> 10 | H15: =IF(A15="","",IF(E15<=0,10,ROUND(MAX(1,MIN(10,10-(E15/MAX(1,$E$7)*10))),1))) -> 5.5 | I15: =IF(A15="","",ROUND(MIN(10,MAX(1, ((11-G15)*0.45)+ ((11-H15)*0.25)+ (MIN(10,E15/2)*0.2)+ (IF(C15="NOW",1,IF(C15="THIS YEAR",2,IF(C15="1 YEAR",3,IF(C15="1-3 YEARS",5,IF(C15="3 YEARS",7,6)))))*0.1) )),1)) -> 3.8 | J15: =IF(A15="","",ROUND((G15*0.4)+(H15*0.3)+((11-I15)*0.3),1)) -> 7.8 | K15: =IF(A15="","",ROUND( (MAX(1,MIN(10,IF(D15<=0,10,(MAX(0,$E$4-$E$8)+($E$6*12))/D15*10)))*0.4) + (MIN(10,H15+0.5)*0.3) + (MIN(10,12-I15)*0.3) ,1)) -> 8.3 | L15: =IF(A15="","",ROUND( (MAX(1,MIN(10,IF(D15<=0,10,(MAX(0,$E$4-$E$8)+($E$6*36))/D15*10)))*0.4) + (MIN(10,H15+1.5)*0.3) + (MIN(10,14-I15)*0.3) ,1)) -> 9.1 | M15: =IF(A15="","",ROUND((F15*0.45)+(J15*0.4)+((11-I15)*0.15),2)) -> 8.25 | N15: =IFERROR(__xludf.DUMMYFUNCTION("IF(A15="""","""",RANK(M15,FILTER($M$11:$M$100,$A$11:$A$100<>""""),0))"),11.0) -> 11 | O15: =IF(A15="","",IF(AND(F15>=8,J15<4),"DREAM",IF(J15>=8,"DO NOW",IF(J15>=6,"START PLANNING",IF(K15>=7,"BUILD TOWARDS","PARK"))))) -> START PLANNING | P15: =IF(A15="","",IF(J15>=9,"NONE",IF(G15<=H15,IF(G15<=11-I15,"MONEY","DIFFICULTY"),IF(H15<=11-I15,"TIME","DIFFICULTY")))) -> TIME | R15: =IF(A15="","",MAX(0,D15-MAX(0,$E$4-$E$8))) -> 0 | S15: =IF(A15="","",IF(R15=0,0,IF($E$6<=0,"NO SAVINGS",ROUNDUP(R15/$E$6,0)))) -> 0 | T15: =IFERROR(__xludf.DUMMYFUNCTION("IF(A15="""","""",RANK(F15,FILTER($F$11:$F$100,$A$11:$A$100<>""""),0))"),5.0) -> 5 | U15: =IFERROR(__xludf.DUMMYFUNCTION("IF(A15="""","""",RANK( (F15*0.5+K15*0.5), FILTER($F$11:$F$100*0.5+$K$11:$K$100*0.5,$A$11:$A$100<>""""), 0))"),6.0) -> 6 | V15: =IFERROR(__xludf.DUMMYFUNCTION("IF(A15="""","""",RANK( (F15*0.65+L15*0.35), FILTER($F$11:$F$100*0.65+$L$11:$L$100*0.35,$A$11:$A$100<>""""), 0))"),5.0) -> 5
A16: Tidy Room Daily | B16: Personal | C16: NOW | D16: 0 | E16: 2 | F16: 6 | G16: =IF(A16="","",IF(D16<=0,10,ROUND(MAX(1,MIN(10,(MAX(0,$E$4-$E$8)/D16)*10)),1))) -> 10 | H16: =IF(A16="","",IF(E16<=0,10,ROUND(MAX(1,MIN(10,10-(E16/MAX(1,$E$7)*10))),1))) -> 9.5 | I16: =IF(A16="","",ROUND(MIN(10,MAX(1, ((11-G16)*0.45)+ ((11-H16)*0.25)+ (MIN(10,E16/2)*0.2)+ (IF(C16="NOW",1,IF(C16="THIS YEAR",2,IF(C16="1 YEAR",3,IF(C16="1-3 YEARS",5,IF(C16="3 YEARS",7,6)))))*0.1) )),1)) -> 1.1 | J16: =IF(A16="","",ROUND((G16*0.4)+(H16*0.3)+((11-I16)*0.3),1)) -> 9.8 | K16: =IF(A16="","",ROUND( (MAX(1,MIN(10,IF(D16<=0,10,(MAX(0,$E$4-$E$8)+($E$6*12))/D16*10)))*0.4) + (MIN(10,H16+0.5)*0.3) + (MIN(10,12-I16)*0.3) ,1)) -> 10 | L16: =IF(A16="","",ROUND( (MAX(1,MIN(10,IF(D16<=0,10,(MAX(0,$E$4-$E$8)+($E$6*36))/D16*10)))*0.4) + (MIN(10,H16+1.5)*0.3) + (MIN(10,14-I16)*0.3) ,1)) -> 10 | M16: =IF(A16="","",ROUND((F16*0.45)+(J16*0.4)+((11-I16)*0.15),2)) -> 8.11 | N16: =IFERROR(__xludf.DUMMYFUNCTION("IF(A16="""","""",RANK(M16,FILTER($M$11:$M$100,$A$11:$A$100<>""""),0))"),12.0) -> 12 | O16: =IF(A16="","",IF(AND(F16>=8,J16<4),"DREAM",IF(J16>=8,"DO NOW",IF(J16>=6,"START PLANNING",IF(K16>=7,"BUILD TOWARDS","PARK"))))) -> DO NOW | P16: =IF(A16="","",IF(J16>=9,"NONE",IF(G16<=H16,IF(G16<=11-I16,"MONEY","DIFFICULTY"),IF(H16<=11-I16,"TIME","DIFFICULTY")))) -> NONE | R16: =IF(A16="","",MAX(0,D16-MAX(0,$E$4-$E$8))) -> 0 | S16: =IF(A16="","",IF(R16=0,0,IF($E$6<=0,"NO SAVINGS",ROUNDUP(R16/$E$6,0)))) -> 0 | T16: =IFERROR(__xludf.DUMMYFUNCTION("IF(A16="""","""",RANK(F16,FILTER($F$11:$F$100,$A$11:$A$100<>""""),0))"),14.0) -> 14 | U16: =IFERROR(__xludf.DUMMYFUNCTION("IF(A16="""","""",RANK( (F16*0.5+K16*0.5), FILTER($F$11:$F$100*0.5+$K$11:$K$100*0.5,$A$11:$A$100<>""""), 0))"),13.0) -> 13 | V16: =IFERROR(__xludf.DUMMYFUNCTION("IF(A16="""","""",RANK( (F16*0.65+L16*0.35), FILTER($F$11:$F$100*0.65+$L$11:$L$100*0.35,$A$11:$A$100<>""""), 0))"),14.0) -> 14
A17: Look into USA semester/term abroad for 3rd year | B17: University | C17: THIS YEAR | D17: 0 | E17: 1 | F17: 7 | G17: =IF(A17="","",IF(D17<=0,10,ROUND(MAX(1,MIN(10,(MAX(0,$E$4-$E$8)/D17)*10)),1))) -> 10 | H17: =IF(A17="","",IF(E17<=0,10,ROUND(MAX(1,MIN(10,10-(E17/MAX(1,$E$7)*10))),1))) -> 9.8 | I17: =IF(A17="","",ROUND(MIN(10,MAX(1, ((11-G17)*0.45)+ ((11-H17)*0.25)+ (MIN(10,E17/2)*0.2)+ (IF(C17="NOW",1,IF(C17="THIS YEAR",2,IF(C17="1 YEAR",3,IF(C17="1-3 YEARS",5,IF(C17="3 YEARS",7,6)))))*0.1) )),1)) -> 1.1 | J17: =IF(A17="","",ROUND((G17*0.4)+(H17*0.3)+((11-I17)*0.3),1)) -> 9.9 | K17: =IF(A17="","",ROUND( (MAX(1,MIN(10,IF(D17<=0,10,(MAX(0,$E$4-$E$8)+($E$6*12))/D17*10)))*0.4) + (MIN(10,H17+0.5)*0.3) + (MIN(10,12-I17)*0.3) ,1)) -> 10 | L17: =IF(A17="","",ROUND( (MAX(1,MIN(10,IF(D17<=0,10,(MAX(0,$E$4-$E$8)+($E$6*36))/D17*10)))*0.4) + (MIN(10,H17+1.5)*0.3) + (MIN(10,14-I17)*0.3) ,1)) -> 10 | M17: =IF(A17="","",ROUND((F17*0.45)+(J17*0.4)+((11-I17)*0.15),2)) -> 8.6 | N17: =IFERROR(__xludf.DUMMYFUNCTION("IF(A17="""","""",RANK(M17,FILTER($M$11:$M$100,$A$11:$A$100<>""""),0))"),7.0) -> 7 | O17: =IF(A17="","",IF(AND(F17>=8,J17<4),"DREAM",IF(J17>=8,"DO NOW",IF(J17>=6,"START PLANNING",IF(K17>=7,"BUILD TOWARDS","PARK"))))) -> DO NOW | P17: =IF(A17="","",IF(J17>=9,"NONE",IF(G17<=H17,IF(G17<=11-I17,"MONEY","DIFFICULTY"),IF(H17<=11-I17,"TIME","DIFFICULTY")))) -> NONE | R17: =IF(A17="","",MAX(0,D17-MAX(0,$E$4-$E$8))) -> 0 | S17: =IF(A17="","",IF(R17=0,0,IF($E$6<=0,"NO SAVINGS",ROUNDUP(R17/$E$6,0)))) -> 0 | T17: =IFERROR(__xludf.DUMMYFUNCTION("IF(A17="""","""",RANK(F17,FILTER($F$11:$F$100,$A$11:$A$100<>""""),0))"),9.0) -> 9 | U17: =IFERROR(__xludf.DUMMYFUNCTION("IF(A17="""","""",RANK( (F17*0.5+K17*0.5), FILTER($F$11:$F$100*0.5+$K$11:$K$100*0.5,$A$11:$A$100<>""""), 0))"),7.0) -> 7 | V17: =IFERROR(__xludf.DUMMYFUNCTION("IF(A17="""","""",RANK( (F17*0.65+L17*0.35), FILTER($F$11:$F$100*0.65+$L$11:$L$100*0.35,$A$11:$A$100<>""""), 0))"),9.0) -> 9
A18: Go to the gym 4x a week | B18: Health/Fitness | C18: NOW | D18: 100 | E18: 6 | F18: 10 | G18: =IF(A18="","",IF(D18<=0,10,ROUND(MAX(1,MIN(10,(MAX(0,$E$4-$E$8)/D18)*10)),1))) -> 10 | H18: =IF(A18="","",IF(E18<=0,10,ROUND(MAX(1,MIN(10,10-(E18/MAX(1,$E$7)*10))),1))) -> 8.5 | I18: =IF(A18="","",ROUND(MIN(10,MAX(1, ((11-G18)*0.45)+ ((11-H18)*0.25)+ (MIN(10,E18/2)*0.2)+ (IF(C18="NOW",1,IF(C18="THIS YEAR",2,IF(C18="1 YEAR",3,IF(C18="1-3 YEARS",5,IF(C18="3 YEARS",7,6)))))*0.1) )),1)) -> 1.8 | J18: =IF(A18="","",ROUND((G18*0.4)+(H18*0.3)+((11-I18)*0.3),1)) -> 9.3 | K18: =IF(A18="","",ROUND( (MAX(1,MIN(10,IF(D18<=0,10,(MAX(0,$E$4-$E$8)+($E$6*12))/D18*10)))*0.4) + (MIN(10,H18+0.5)*0.3) + (MIN(10,12-I18)*0.3) ,1)) -> 9.7 | L18: =IF(A18="","",ROUND( (MAX(1,MIN(10,IF(D18<=0,10,(MAX(0,$E$4-$E$8)+($E$6*36))/D18*10)))*0.4) + (MIN(10,H18+1.5)*0.3) + (MIN(10,14-I18)*0.3) ,1)) -> 10 | M18: =IF(A18="","",ROUND((F18*0.45)+(J18*0.4)+((11-I18)*0.15),2)) -> 9.6 | N18: =IFERROR(__xludf.DUMMYFUNCTION("IF(A18="""","""",RANK(M18,FILTER($M$11:$M$100,$A$11:$A$100<>""""),0))"),1.0) -> 1 | O18: =IF(A18="","",IF(AND(F18>=8,J18<4),"DREAM",IF(J18>=8,"DO NOW",IF(J18>=6,"START PLANNING",IF(K18>=7,"BUILD TOWARDS","PARK"))))) -> DO NOW | P18: =IF(A18="","",IF(J18>=9,"NONE",IF(G18<=H18,IF(G18<=11-I18,"MONEY","DIFFICULTY"),IF(H18<=11-I18,"TIME","DIFFICULTY")))) -> NONE | R18: =IF(A18="","",MAX(0,D18-MAX(0,$E$4-$E$8))) -> 0 | S18: =IF(A18="","",IF(R18=0,0,IF($E$6<=0,"NO SAVINGS",ROUNDUP(R18/$E$6,0)))) -> 0 | T18: =IFERROR(__xludf.DUMMYFUNCTION("IF(A18="""","""",RANK(F18,FILTER($F$11:$F$100,$A$11:$A$100<>""""),0))"),1.0) -> 1 | U18: =IFERROR(__xludf.DUMMYFUNCTION("IF(A18="""","""",RANK( (F18*0.5+K18*0.5), FILTER($F$11:$F$100*0.5+$K$11:$K$100*0.5,$A$11:$A$100<>""""), 0))"),1.0) -> 1 | V18: =IFERROR(__xludf.DUMMYFUNCTION("IF(A18="""","""",RANK( (F18*0.65+L18*0.35), FILTER($F$11:$F$100*0.65+$L$11:$L$100*0.35,$A$11:$A$100<>""""), 0))"),1.0) -> 1
A19: Give £20 money from weekly uni money to Mum | B19: Money | C19: THIS YEAR | D19: 0 | E19: 0 | F19: 7 | G19: =IF(A19="","",IF(D19<=0,10,ROUND(MAX(1,MIN(10,(MAX(0,$E$4-$E$8)/D19)*10)),1))) -> 10 | H19: =IF(A19="","",IF(E19<=0,10,ROUND(MAX(1,MIN(10,10-(E19/MAX(1,$E$7)*10))),1))) -> 10 | I19: =IF(A19="","",ROUND(MIN(10,MAX(1, ((11-G19)*0.45)+ ((11-H19)*0.25)+ (MIN(10,E19/2)*0.2)+ (IF(C19="NOW",1,IF(C19="THIS YEAR",2,IF(C19="1 YEAR",3,IF(C19="1-3 YEARS",5,IF(C19="3 YEARS",7,6)))))*0.1) )),1)) -> 1 | J19: =IF(A19="","",ROUND((G19*0.4)+(H19*0.3)+((11-I19)*0.3),1)) -> 10 | K19: =IF(A19="","",ROUND( (MAX(1,MIN(10,IF(D19<=0,10,(MAX(0,$E$4-$E$8)+($E$6*12))/D19*10)))*0.4) + (MIN(10,H19+0.5)*0.3) + (MIN(10,12-I19)*0.3) ,1)) -> 10 | L19: =IF(A19="","",ROUND( (MAX(1,MIN(10,IF(D19<=0,10,(MAX(0,$E$4-$E$8)+($E$6*36))/D19*10)))*0.4) + (MIN(10,H19+1.5)*0.3) + (MIN(10,14-I19)*0.3) ,1)) -> 10 | M19: =IF(A19="","",ROUND((F19*0.45)+(J19*0.4)+((11-I19)*0.15),2)) -> 8.65 | N19: =IFERROR(__xludf.DUMMYFUNCTION("IF(A19="""","""",RANK(M19,FILTER($M$11:$M$100,$A$11:$A$100<>""""),0))"),6.0) -> 6 | O19: =IF(A19="","",IF(AND(F19>=8,J19<4),"DREAM",IF(J19>=8,"DO NOW",IF(J19>=6,"START PLANNING",IF(K19>=7,"BUILD TOWARDS","PARK"))))) -> DO NOW | P19: =IF(A19="","",IF(J19>=9,"NONE",IF(G19<=H19,IF(G19<=11-I19,"MONEY","DIFFICULTY"),IF(H19<=11-I19,"TIME","DIFFICULTY")))) -> NONE | R19: =IF(A19="","",MAX(0,D19-MAX(0,$E$4-$E$8))) -> 0 | S19: =IF(A19="","",IF(R19=0,0,IF($E$6<=0,"NO SAVINGS",ROUNDUP(R19/$E$6,0)))) -> 0 | T19: =IFERROR(__xludf.DUMMYFUNCTION("IF(A19="""","""",RANK(F19,FILTER($F$11:$F$100,$A$11:$A$100<>""""),0))"),9.0) -> 9 | U19: =IFERROR(__xludf.DUMMYFUNCTION("IF(A19="""","""",RANK( (F19*0.5+K19*0.5), FILTER($F$11:$F$100*0.5+$K$11:$K$100*0.5,$A$11:$A$100<>""""), 0))"),7.0) -> 7 | V19: =IFERROR(__xludf.DUMMYFUNCTION("IF(A19="""","""",RANK( (F19*0.65+L19*0.35), FILTER($F$11:$F$100*0.65+$L$11:$L$100*0.35,$A$11:$A$100<>""""), 0))"),9.0) -> 9
